[2024-07-18 20:20:55 +0900] [595] [INFO] Starting gunicorn 22.0.0
[2024-07-18 20:20:55 +0900] [595] [INFO] Listening at: unix:/var/run/gunicorn/gunicorn.sock (595)
[2024-07-18 20:20:55 +0900] [595] [INFO] Using worker: sync
[2024-07-18 20:20:55 +0900] [596] [INFO] Booting worker with pid: 596
[2024-07-18 20:21:17 +0900] [596] [INFO] Worker reloading: /home/web_ai/Project/app/main/routes.py modified
[2024-07-18 20:21:17 +0900] [596] [INFO] Worker exiting (pid: 596)
[2024-07-18 20:21:17 +0900] [615] [INFO] Booting worker with pid: 615
 - - [18/Jul/2024:20:22:46 +0900] "GET / HTTP/1.0" 200 8290 "-" "Mozilla/5.0 (Windows NT 10.0; Win64; x64) AppleWebKit/537.36 (KHTML, like Gecko) Chrome/126.0.0.0 Safari/537.36 Edg/126.0.0.0"
 - - [18/Jul/2024:20:22:46 +0900] "GET /static/css/index.css HTTP/1.0" 304 0 "http://61.43.54.35:8484/" "Mozilla/5.0 (Windows NT 10.0; Win64; x64) AppleWebKit/537.36 (KHTML, like Gecko) Chrome/126.0.0.0 Safari/537.36 Edg/126.0.0.0"
 - - [18/Jul/2024:20:22:46 +0900] "GET /static/scripts/index.js HTTP/1.0" 304 0 "http://61.43.54.35:8484/" "Mozilla/5.0 (Windows NT 10.0; Win64; x64) AppleWebKit/537.36 (KHTML, like Gecko) Chrome/126.0.0.0 Safari/537.36 Edg/126.0.0.0"
 - - [18/Jul/2024:20:22:46 +0900] "GET /static/css/summary.css HTTP/1.0" 304 0 "http://61.43.54.35:8484/" "Mozilla/5.0 (Windows NT 10.0; Win64; x64) AppleWebKit/537.36 (KHTML, like Gecko) Chrome/126.0.0.0 Safari/537.36 Edg/126.0.0.0"
 - - [18/Jul/2024:20:22:46 +0900] "GET /static/scripts/summary.js HTTP/1.0" 304 0 "http://61.43.54.35:8484/" "Mozilla/5.0 (Windows NT 10.0; Win64; x64) AppleWebKit/537.36 (KHTML, like Gecko) Chrome/126.0.0.0 Safari/537.36 Edg/126.0.0.0"
 - - [18/Jul/2024:20:27:59 +0900] "GET /load_content/dpo_data?lastViewNumber=1 HTTP/1.0" 200 7420 "http://61.43.54.35:8484/" "Mozilla/5.0 (Windows NT 10.0; Win64; x64) AppleWebKit/537.36 (KHTML, like Gecko) Chrome/126.0.0.0 Safari/537.36 Edg/126.0.0.0"
 - - [18/Jul/2024:20:27:59 +0900] "GET /static/css/dpo_data.css HTTP/1.0" 304 0 "http://61.43.54.35:8484/" "Mozilla/5.0 (Windows NT 10.0; Win64; x64) AppleWebKit/537.36 (KHTML, like Gecko) Chrome/126.0.0.0 Safari/537.36 Edg/126.0.0.0"
 - - [18/Jul/2024:20:27:59 +0900] "GET /static/scripts/dpo_data.js HTTP/1.0" 304 0 "http://61.43.54.35:8484/" "Mozilla/5.0 (Windows NT 10.0; Win64; x64) AppleWebKit/537.36 (KHTML, like Gecko) Chrome/126.0.0.0 Safari/537.36 Edg/126.0.0.0"
 - - [18/Jul/2024:20:28:19 +0900] "POST /util/aws_db_api HTTP/1.0" 200 10700 "http://61.43.54.35:8484/" "Mozilla/5.0 (Windows NT 10.0; Win64; x64) AppleWebKit/537.36 (KHTML, like Gecko) Chrome/126.0.0.0 Safari/537.36 Edg/126.0.0.0"
 - - [18/Jul/2024:20:30:30 +0900] "POST /util/model_api HTTP/1.0" 200 3 "http://61.43.54.35:8484/" "Mozilla/5.0 (Windows NT 10.0; Win64; x64) AppleWebKit/537.36 (KHTML, like Gecko) Chrome/126.0.0.0 Safari/537.36 Edg/126.0.0.0"
 - - [18/Jul/2024:20:33:44 +0900] "GET /load_content/db_manager?lastViewNumber=1 HTTP/1.0" 200 4338 "http://61.43.54.35:8484/" "Mozilla/5.0 (Windows NT 10.0; Win64; x64) AppleWebKit/537.36 (KHTML, like Gecko) Chrome/126.0.0.0 Safari/537.36 Edg/126.0.0.0"
 - - [18/Jul/2024:20:33:44 +0900] "GET /static/css/db_manager.css HTTP/1.0" 304 0 "http://61.43.54.35:8484/" "Mozilla/5.0 (Windows NT 10.0; Win64; x64) AppleWebKit/537.36 (KHTML, like Gecko) Chrome/126.0.0.0 Safari/537.36 Edg/126.0.0.0"
 - - [18/Jul/2024:20:33:44 +0900] "GET /static/scripts/db_manager.js HTTP/1.0" 304 0 "http://61.43.54.35:8484/" "Mozilla/5.0 (Windows NT 10.0; Win64; x64) AppleWebKit/537.36 (KHTML, like Gecko) Chrome/126.0.0.0 Safari/537.36 Edg/126.0.0.0"
[2024-07-18 20:37:01,401] ERROR in app: Exception on /util/data_api [POST]
Traceback (most recent call last):
  File "/home/web_ai/Project/venv/lib/python3.11/site-packages/urllib3/connection.py", line 196, in _new_conn
    sock = connection.create_connection(
           ^^^^^^^^^^^^^^^^^^^^^^^^^^^^^
  File "/home/web_ai/Project/venv/lib/python3.11/site-packages/urllib3/util/connection.py", line 85, in create_connection
    raise err
  File "/home/web_ai/Project/venv/lib/python3.11/site-packages/urllib3/util/connection.py", line 73, in create_connection
    sock.connect(sa)
TimeoutError: [Errno 110] Connection timed out

The above exception was the direct cause of the following exception:

Traceback (most recent call last):
  File "/home/web_ai/Project/venv/lib/python3.11/site-packages/urllib3/connectionpool.py", line 789, in urlopen
    response = self._make_request(
               ^^^^^^^^^^^^^^^^^^^
  File "/home/web_ai/Project/venv/lib/python3.11/site-packages/urllib3/connectionpool.py", line 495, in _make_request
    conn.request(
  File "/home/web_ai/Project/venv/lib/python3.11/site-packages/urllib3/connection.py", line 398, in request
    self.endheaders()
  File "/usr/lib/python3.11/http/client.py", line 1298, in endheaders
    self._send_output(message_body, encode_chunked=encode_chunked)
  File "/usr/lib/python3.11/http/client.py", line 1058, in _send_output
    self.send(msg)
  File "/usr/lib/python3.11/http/client.py", line 996, in send
    self.connect()
  File "/home/web_ai/Project/venv/lib/python3.11/site-packages/urllib3/connection.py", line 236, in connect
    self.sock = self._new_conn()
                ^^^^^^^^^^^^^^^^
  File "/home/web_ai/Project/venv/lib/python3.11/site-packages/urllib3/connection.py", line 205, in _new_conn
    raise ConnectTimeoutError(
urllib3.exceptions.ConnectTimeoutError: (<urllib3.connection.HTTPConnection object at 0x7f27539c3150>, 'Connection to 10.34.120.28 timed out. (connect timeout=None)')

The above exception was the direct cause of the following exception:

Traceback (most recent call last):
  File "/home/web_ai/Project/venv/lib/python3.11/site-packages/requests/adapters.py", line 667, in send
    resp = conn.urlopen(
           ^^^^^^^^^^^^^
  File "/home/web_ai/Project/venv/lib/python3.11/site-packages/urllib3/connectionpool.py", line 843, in urlopen
    retries = retries.increment(
              ^^^^^^^^^^^^^^^^^^
  File "/home/web_ai/Project/venv/lib/python3.11/site-packages/urllib3/util/retry.py", line 519, in increment
    raise MaxRetryError(_pool, url, reason) from reason  # type: ignore[arg-type]
    ^^^^^^^^^^^^^^^^^^^^^^^^^^^^^^^^^^^^^^^^^^^^^^^^^^^
urllib3.exceptions.MaxRetryError: HTTPConnectionPool(host='10.34.120.28', port=8282): Max retries exceeded with url: /api (Caused by ConnectTimeoutError(<urllib3.connection.HTTPConnection object at 0x7f27539c3150>, 'Connection to 10.34.120.28 timed out. (connect timeout=None)'))

During handling of the above exception, another exception occurred:

Traceback (most recent call last):
  File "/home/web_ai/Project/venv/lib/python3.11/site-packages/flask/app.py", line 1473, in wsgi_app
    response = self.full_dispatch_request()
               ^^^^^^^^^^^^^^^^^^^^^^^^^^^^
  File "/home/web_ai/Project/venv/lib/python3.11/site-packages/flask/app.py", line 882, in full_dispatch_request
    rv = self.handle_user_exception(e)
         ^^^^^^^^^^^^^^^^^^^^^^^^^^^^^
  File "/home/web_ai/Project/venv/lib/python3.11/site-packages/flask/app.py", line 880, in full_dispatch_request
    rv = self.dispatch_request()
         ^^^^^^^^^^^^^^^^^^^^^^^
  File "/home/web_ai/Project/venv/lib/python3.11/site-packages/flask/app.py", line 865, in dispatch_request
    return self.ensure_sync(self.view_functions[rule.endpoint])(**view_args)  # type: ignore[no-any-return]
           ^^^^^^^^^^^^^^^^^^^^^^^^^^^^^^^^^^^^^^^^^^^^^^^^^^^^^^^^^^^^^^^^^
  File "/home/web_ai/Project/app/main/routes.py", line 389, in data_api
    response = requests.post(DATA_API_ADDRESS, data=data)
               ^^^^^^^^^^^^^^^^^^^^^^^^^^^^^^^^^^^^^^^^^^
  File "/home/web_ai/Project/venv/lib/python3.11/site-packages/requests/api.py", line 115, in post
    return request("post", url, data=data, json=json, **kwargs)
           ^^^^^^^^^^^^^^^^^^^^^^^^^^^^^^^^^^^^^^^^^^^^^^^^^^^^
  File "/home/web_ai/Project/venv/lib/python3.11/site-packages/requests/api.py", line 59, in request
    return session.request(method=method, url=url, **kwargs)
           ^^^^^^^^^^^^^^^^^^^^^^^^^^^^^^^^^^^^^^^^^^^^^^^^^
  File "/home/web_ai/Project/venv/lib/python3.11/site-packages/requests/sessions.py", line 589, in request
    resp = self.send(prep, **send_kwargs)
           ^^^^^^^^^^^^^^^^^^^^^^^^^^^^^^
  File "/home/web_ai/Project/venv/lib/python3.11/site-packages/requests/sessions.py", line 703, in send
    r = adapter.send(request, **kwargs)
        ^^^^^^^^^^^^^^^^^^^^^^^^^^^^^^^
  File "/home/web_ai/Project/venv/lib/python3.11/site-packages/requests/adapters.py", line 688, in send
    raise ConnectTimeout(e, request=request)
requests.exceptions.ConnectTimeout: HTTPConnectionPool(host='10.34.120.28', port=8282): Max retries exceeded with url: /api (Caused by ConnectTimeoutError(<urllib3.connection.HTTPConnection object at 0x7f27539c3150>, 'Connection to 10.34.120.28 timed out. (connect timeout=None)'))
여기까지 ImmutableMultiDict([])
 - - [18/Jul/2024:20:37:01 +0900] "POST /util/data_api HTTP/1.0" 500 265 "http://61.43.54.35:8484/" "Mozilla/5.0 (Windows NT 10.0; Win64; x64) AppleWebKit/537.36 (KHTML, like Gecko) Chrome/126.0.0.0 Safari/537.36 Edg/126.0.0.0"
[2024-07-18 20:48:13 +0900] [615] [INFO] Worker reloading: /home/web_ai/Project/app/secret/secret.py modified
[2024-07-18 20:48:13 +0900] [615] [INFO] Worker exiting (pid: 615)
[2024-07-18 20:48:13 +0900] [664] [INFO] Booting worker with pid: 664
 - - [18/Jul/2024:20:48:22 +0900] "GET /load_content/summary?lastViewNumber=1 HTTP/1.0" 200 6258 "http://61.43.54.35:8484/" "Mozilla/5.0 (Windows NT 10.0; Win64; x64) AppleWebKit/537.36 (KHTML, like Gecko) Chrome/126.0.0.0 Safari/537.36 Edg/126.0.0.0"
 - - [18/Jul/2024:20:48:22 +0900] "GET /static/css/summary.css HTTP/1.0" 304 0 "http://61.43.54.35:8484/" "Mozilla/5.0 (Windows NT 10.0; Win64; x64) AppleWebKit/537.36 (KHTML, like Gecko) Chrome/126.0.0.0 Safari/537.36 Edg/126.0.0.0"
 - - [18/Jul/2024:20:48:22 +0900] "GET /static/scripts/summary.js HTTP/1.0" 304 0 "http://61.43.54.35:8484/" "Mozilla/5.0 (Windows NT 10.0; Win64; x64) AppleWebKit/537.36 (KHTML, like Gecko) Chrome/126.0.0.0 Safari/537.36 Edg/126.0.0.0"
 - - [18/Jul/2024:20:48:23 +0900] "GET /load_content/db_manager?lastViewNumber=1 HTTP/1.0" 200 4338 "http://61.43.54.35:8484/" "Mozilla/5.0 (Windows NT 10.0; Win64; x64) AppleWebKit/537.36 (KHTML, like Gecko) Chrome/126.0.0.0 Safari/537.36 Edg/126.0.0.0"
 - - [18/Jul/2024:20:48:23 +0900] "GET /static/css/db_manager.css HTTP/1.0" 304 0 "http://61.43.54.35:8484/" "Mozilla/5.0 (Windows NT 10.0; Win64; x64) AppleWebKit/537.36 (KHTML, like Gecko) Chrome/126.0.0.0 Safari/537.36 Edg/126.0.0.0"
 - - [18/Jul/2024:20:48:23 +0900] "GET /static/scripts/db_manager.js HTTP/1.0" 304 0 "http://61.43.54.35:8484/" "Mozilla/5.0 (Windows NT 10.0; Win64; x64) AppleWebKit/537.36 (KHTML, like Gecko) Chrome/126.0.0.0 Safari/537.36 Edg/126.0.0.0"
[2024-07-18 20:50:36,505] ERROR in app: Exception on /util/data_api [POST]
Traceback (most recent call last):
  File "/home/web_ai/Project/venv/lib/python3.11/site-packages/urllib3/connection.py", line 196, in _new_conn
    sock = connection.create_connection(
           ^^^^^^^^^^^^^^^^^^^^^^^^^^^^^
  File "/home/web_ai/Project/venv/lib/python3.11/site-packages/urllib3/util/connection.py", line 85, in create_connection
    raise err
  File "/home/web_ai/Project/venv/lib/python3.11/site-packages/urllib3/util/connection.py", line 73, in create_connection
    sock.connect(sa)
TimeoutError: [Errno 110] Connection timed out

The above exception was the direct cause of the following exception:

Traceback (most recent call last):
  File "/home/web_ai/Project/venv/lib/python3.11/site-packages/urllib3/connectionpool.py", line 789, in urlopen
    response = self._make_request(
               ^^^^^^^^^^^^^^^^^^^
  File "/home/web_ai/Project/venv/lib/python3.11/site-packages/urllib3/connectionpool.py", line 495, in _make_request
    conn.request(
  File "/home/web_ai/Project/venv/lib/python3.11/site-packages/urllib3/connection.py", line 398, in request
    self.endheaders()
  File "/usr/lib/python3.11/http/client.py", line 1298, in endheaders
    self._send_output(message_body, encode_chunked=encode_chunked)
  File "/usr/lib/python3.11/http/client.py", line 1058, in _send_output
    self.send(msg)
  File "/usr/lib/python3.11/http/client.py", line 996, in send
    self.connect()
  File "/home/web_ai/Project/venv/lib/python3.11/site-packages/urllib3/connection.py", line 236, in connect
    self.sock = self._new_conn()
                ^^^^^^^^^^^^^^^^
  File "/home/web_ai/Project/venv/lib/python3.11/site-packages/urllib3/connection.py", line 205, in _new_conn
    raise ConnectTimeoutError(
urllib3.exceptions.ConnectTimeoutError: (<urllib3.connection.HTTPConnection object at 0x7f27539c04d0>, 'Connection to 61.43.54.35 timed out. (connect timeout=None)')

The above exception was the direct cause of the following exception:

Traceback (most recent call last):
  File "/home/web_ai/Project/venv/lib/python3.11/site-packages/requests/adapters.py", line 667, in send
    resp = conn.urlopen(
           ^^^^^^^^^^^^^
  File "/home/web_ai/Project/venv/lib/python3.11/site-packages/urllib3/connectionpool.py", line 843, in urlopen
    retries = retries.increment(
              ^^^^^^^^^^^^^^^^^^
  File "/home/web_ai/Project/venv/lib/python3.11/site-packages/urllib3/util/retry.py", line 519, in increment
    raise MaxRetryError(_pool, url, reason) from reason  # type: ignore[arg-type]
    ^^^^^^^^^^^^^^^^^^^^^^^^^^^^^^^^^^^^^^^^^^^^^^^^^^^
urllib3.exceptions.MaxRetryError: HTTPConnectionPool(host='61.43.54.35', port=8282): Max retries exceeded with url: /api (Caused by ConnectTimeoutError(<urllib3.connection.HTTPConnection object at 0x7f27539c04d0>, 'Connection to 61.43.54.35 timed out. (connect timeout=None)'))

During handling of the above exception, another exception occurred:

Traceback (most recent call last):
  File "/home/web_ai/Project/venv/lib/python3.11/site-packages/flask/app.py", line 1473, in wsgi_app
    response = self.full_dispatch_request()
               ^^^^^^^^^^^^^^^^^^^^^^^^^^^^
  File "/home/web_ai/Project/venv/lib/python3.11/site-packages/flask/app.py", line 882, in full_dispatch_request
    rv = self.handle_user_exception(e)
         ^^^^^^^^^^^^^^^^^^^^^^^^^^^^^
  File "/home/web_ai/Project/venv/lib/python3.11/site-packages/flask/app.py", line 880, in full_dispatch_request
    rv = self.dispatch_request()
         ^^^^^^^^^^^^^^^^^^^^^^^
  File "/home/web_ai/Project/venv/lib/python3.11/site-packages/flask/app.py", line 865, in dispatch_request
    return self.ensure_sync(self.view_functions[rule.endpoint])(**view_args)  # type: ignore[no-any-return]
           ^^^^^^^^^^^^^^^^^^^^^^^^^^^^^^^^^^^^^^^^^^^^^^^^^^^^^^^^^^^^^^^^^
  File "/home/web_ai/Project/app/main/routes.py", line 389, in data_api
    response = requests.post(DATA_API_ADDRESS, data=data)
               ^^^^^^^^^^^^^^^^^^^^^^^^^^^^^^^^^^^^^^^^^^
  File "/home/web_ai/Project/venv/lib/python3.11/site-packages/requests/api.py", line 115, in post
    return request("post", url, data=data, json=json, **kwargs)
           ^^^^^^^^^^^^^^^^^^^^^^^^^^^^^^^^^^^^^^^^^^^^^^^^^^^^
  File "/home/web_ai/Project/venv/lib/python3.11/site-packages/requests/api.py", line 59, in request
    return session.request(method=method, url=url, **kwargs)
           ^^^^^^^^^^^^^^^^^^^^^^^^^^^^^^^^^^^^^^^^^^^^^^^^^
  File "/home/web_ai/Project/venv/lib/python3.11/site-packages/requests/sessions.py", line 589, in request
    resp = self.send(prep, **send_kwargs)
           ^^^^^^^^^^^^^^^^^^^^^^^^^^^^^^
  File "/home/web_ai/Project/venv/lib/python3.11/site-packages/requests/sessions.py", line 703, in send
    r = adapter.send(request, **kwargs)
        ^^^^^^^^^^^^^^^^^^^^^^^^^^^^^^^
  File "/home/web_ai/Project/venv/lib/python3.11/site-packages/requests/adapters.py", line 688, in send
    raise ConnectTimeout(e, request=request)
requests.exceptions.ConnectTimeout: HTTPConnectionPool(host='61.43.54.35', port=8282): Max retries exceeded with url: /api (Caused by ConnectTimeoutError(<urllib3.connection.HTTPConnection object at 0x7f27539c04d0>, 'Connection to 61.43.54.35 timed out. (connect timeout=None)'))
여기까지 ImmutableMultiDict([])
 - - [18/Jul/2024:20:50:36 +0900] "POST /util/data_api HTTP/1.0" 500 265 "http://61.43.54.35:8484/" "Mozilla/5.0 (Windows NT 10.0; Win64; x64) AppleWebKit/537.36 (KHTML, like Gecko) Chrome/126.0.0.0 Safari/537.36 Edg/126.0.0.0"
 - - [18/Jul/2024:20:50:36 +0900] "GET /static/css/index.css HTTP/1.0" 304 0 "http://61.43.54.35:8484/" "Mozilla/5.0 (Windows NT 10.0; Win64; x64) AppleWebKit/537.36 (KHTML, like Gecko) Chrome/126.0.0.0 Safari/537.36 Edg/126.0.0.0"
 - - [18/Jul/2024:20:50:36 +0900] "GET /static/css/db_manager.css HTTP/1.0" 304 0 "http://61.43.54.35:8484/" "Mozilla/5.0 (Windows NT 10.0; Win64; x64) AppleWebKit/537.36 (KHTML, like Gecko) Chrome/126.0.0.0 Safari/537.36 Edg/126.0.0.0"
 - - [18/Jul/2024:20:57:41 +0900] "GET /load_content/summary?lastViewNumber=1 HTTP/1.0" 200 6258 "http://61.43.54.35:8484/" "Mozilla/5.0 (Windows NT 10.0; Win64; x64) AppleWebKit/537.36 (KHTML, like Gecko) Chrome/126.0.0.0 Safari/537.36 Edg/126.0.0.0"
 - - [18/Jul/2024:20:57:41 +0900] "GET /static/css/summary.css HTTP/1.0" 304 0 "http://61.43.54.35:8484/" "Mozilla/5.0 (Windows NT 10.0; Win64; x64) AppleWebKit/537.36 (KHTML, like Gecko) Chrome/126.0.0.0 Safari/537.36 Edg/126.0.0.0"
 - - [18/Jul/2024:20:57:41 +0900] "GET /static/scripts/summary.js HTTP/1.0" 304 0 "http://61.43.54.35:8484/" "Mozilla/5.0 (Windows NT 10.0; Win64; x64) AppleWebKit/537.36 (KHTML, like Gecko) Chrome/126.0.0.0 Safari/537.36 Edg/126.0.0.0"
 - - [18/Jul/2024:20:57:58 +0900] "GET / HTTP/1.0" 200 8290 "-" "Mozilla/5.0 (Windows NT 10.0; Win64; x64) AppleWebKit/537.36 (KHTML, like Gecko) Chrome/126.0.0.0 Safari/537.36 Edg/126.0.0.0"
 - - [18/Jul/2024:20:57:58 +0900] "GET /static/css/index.css HTTP/1.0" 304 0 "http://61.43.54.35:8484/" "Mozilla/5.0 (Windows NT 10.0; Win64; x64) AppleWebKit/537.36 (KHTML, like Gecko) Chrome/126.0.0.0 Safari/537.36 Edg/126.0.0.0"
 - - [18/Jul/2024:20:57:58 +0900] "GET /static/scripts/index.js HTTP/1.0" 304 0 "http://61.43.54.35:8484/" "Mozilla/5.0 (Windows NT 10.0; Win64; x64) AppleWebKit/537.36 (KHTML, like Gecko) Chrome/126.0.0.0 Safari/537.36 Edg/126.0.0.0"
 - - [18/Jul/2024:20:57:58 +0900] "GET /static/css/summary.css HTTP/1.0" 304 0 "http://61.43.54.35:8484/" "Mozilla/5.0 (Windows NT 10.0; Win64; x64) AppleWebKit/537.36 (KHTML, like Gecko) Chrome/126.0.0.0 Safari/537.36 Edg/126.0.0.0"
 - - [18/Jul/2024:20:57:58 +0900] "GET /static/scripts/summary.js HTTP/1.0" 304 0 "http://61.43.54.35:8484/" "Mozilla/5.0 (Windows NT 10.0; Win64; x64) AppleWebKit/537.36 (KHTML, like Gecko) Chrome/126.0.0.0 Safari/537.36 Edg/126.0.0.0"
 - - [18/Jul/2024:20:58:06 +0900] "GET /load_content/db_manager?lastViewNumber=1 HTTP/1.0" 200 4338 "http://61.43.54.35:8484/" "Mozilla/5.0 (Windows NT 10.0; Win64; x64) AppleWebKit/537.36 (KHTML, like Gecko) Chrome/126.0.0.0 Safari/537.36 Edg/126.0.0.0"
 - - [18/Jul/2024:20:58:06 +0900] "GET /static/css/db_manager.css HTTP/1.0" 304 0 "http://61.43.54.35:8484/" "Mozilla/5.0 (Windows NT 10.0; Win64; x64) AppleWebKit/537.36 (KHTML, like Gecko) Chrome/126.0.0.0 Safari/537.36 Edg/126.0.0.0"
 - - [18/Jul/2024:20:58:06 +0900] "GET /static/scripts/db_manager.js HTTP/1.0" 304 0 "http://61.43.54.35:8484/" "Mozilla/5.0 (Windows NT 10.0; Win64; x64) AppleWebKit/537.36 (KHTML, like Gecko) Chrome/126.0.0.0 Safari/537.36 Edg/126.0.0.0"
[2024-07-18 21:00:22,233] ERROR in app: Exception on /util/data_api [POST]
Traceback (most recent call last):
  File "/home/web_ai/Project/venv/lib/python3.11/site-packages/urllib3/connection.py", line 196, in _new_conn
    sock = connection.create_connection(
           ^^^^^^^^^^^^^^^^^^^^^^^^^^^^^
  File "/home/web_ai/Project/venv/lib/python3.11/site-packages/urllib3/util/connection.py", line 85, in create_connection
    raise err
  File "/home/web_ai/Project/venv/lib/python3.11/site-packages/urllib3/util/connection.py", line 73, in create_connection
    sock.connect(sa)
TimeoutError: [Errno 110] Connection timed out

The above exception was the direct cause of the following exception:

Traceback (most recent call last):
  File "/home/web_ai/Project/venv/lib/python3.11/site-packages/urllib3/connectionpool.py", line 789, in urlopen
    response = self._make_request(
               ^^^^^^^^^^^^^^^^^^^
  File "/home/web_ai/Project/venv/lib/python3.11/site-packages/urllib3/connectionpool.py", line 495, in _make_request
    conn.request(
  File "/home/web_ai/Project/venv/lib/python3.11/site-packages/urllib3/connection.py", line 398, in request
    self.endheaders()
  File "/usr/lib/python3.11/http/client.py", line 1298, in endheaders
    self._send_output(message_body, encode_chunked=encode_chunked)
  File "/usr/lib/python3.11/http/client.py", line 1058, in _send_output
    self.send(msg)
  File "/usr/lib/python3.11/http/client.py", line 996, in send
    self.connect()
  File "/home/web_ai/Project/venv/lib/python3.11/site-packages/urllib3/connection.py", line 236, in connect
    self.sock = self._new_conn()
                ^^^^^^^^^^^^^^^^
  File "/home/web_ai/Project/venv/lib/python3.11/site-packages/urllib3/connection.py", line 205, in _new_conn
    raise ConnectTimeoutError(
urllib3.exceptions.ConnectTimeoutError: (<urllib3.connection.HTTPConnection object at 0x7f275306f5d0>, 'Connection to 61.43.54.35 timed out. (connect timeout=None)')

The above exception was the direct cause of the following exception:

Traceback (most recent call last):
  File "/home/web_ai/Project/venv/lib/python3.11/site-packages/requests/adapters.py", line 667, in send
    resp = conn.urlopen(
           ^^^^^^^^^^^^^
  File "/home/web_ai/Project/venv/lib/python3.11/site-packages/urllib3/connectionpool.py", line 843, in urlopen
    retries = retries.increment(
              ^^^^^^^^^^^^^^^^^^
  File "/home/web_ai/Project/venv/lib/python3.11/site-packages/urllib3/util/retry.py", line 519, in increment
    raise MaxRetryError(_pool, url, reason) from reason  # type: ignore[arg-type]
    ^^^^^^^^^^^^^^^^^^^^^^^^^^^^^^^^^^^^^^^^^^^^^^^^^^^
urllib3.exceptions.MaxRetryError: HTTPConnectionPool(host='61.43.54.35', port=8282): Max retries exceeded with url: /api (Caused by ConnectTimeoutError(<urllib3.connection.HTTPConnection object at 0x7f275306f5d0>, 'Connection to 61.43.54.35 timed out. (connect timeout=None)'))

During handling of the above exception, another exception occurred:

Traceback (most recent call last):
  File "/home/web_ai/Project/venv/lib/python3.11/site-packages/flask/app.py", line 1473, in wsgi_app
    response = self.full_dispatch_request()
               ^^^^^^^^^^^^^^^^^^^^^^^^^^^^
  File "/home/web_ai/Project/venv/lib/python3.11/site-packages/flask/app.py", line 882, in full_dispatch_request
    rv = self.handle_user_exception(e)
         ^^^^^^^^^^^^^^^^^^^^^^^^^^^^^
  File "/home/web_ai/Project/venv/lib/python3.11/site-packages/flask/app.py", line 880, in full_dispatch_request
    rv = self.dispatch_request()
         ^^^^^^^^^^^^^^^^^^^^^^^
  File "/home/web_ai/Project/venv/lib/python3.11/site-packages/flask/app.py", line 865, in dispatch_request
    return self.ensure_sync(self.view_functions[rule.endpoint])(**view_args)  # type: ignore[no-any-return]
           ^^^^^^^^^^^^^^^^^^^^^^^^^^^^^^^^^^^^^^^^^^^^^^^^^^^^^^^^^^^^^^^^^
  File "/home/web_ai/Project/app/main/routes.py", line 389, in data_api
    response = requests.post(DATA_API_ADDRESS, data=data)
               ^^^^^^^^^^^^^^^^^^^^^^^^^^^^^^^^^^^^^^^^^^
  File "/home/web_ai/Project/venv/lib/python3.11/site-packages/requests/api.py", line 115, in post
    return request("post", url, data=data, json=json, **kwargs)
           ^^^^^^^^^^^^^^^^^^^^^^^^^^^^^^^^^^^^^^^^^^^^^^^^^^^^
  File "/home/web_ai/Project/venv/lib/python3.11/site-packages/requests/api.py", line 59, in request
    return session.request(method=method, url=url, **kwargs)
           ^^^^^^^^^^^^^^^^^^^^^^^^^^^^^^^^^^^^^^^^^^^^^^^^^
  File "/home/web_ai/Project/venv/lib/python3.11/site-packages/requests/sessions.py", line 589, in request
    resp = self.send(prep, **send_kwargs)
           ^^^^^^^^^^^^^^^^^^^^^^^^^^^^^^
  File "/home/web_ai/Project/venv/lib/python3.11/site-packages/requests/sessions.py", line 703, in send
    r = adapter.send(request, **kwargs)
        ^^^^^^^^^^^^^^^^^^^^^^^^^^^^^^^
  File "/home/web_ai/Project/venv/lib/python3.11/site-packages/requests/adapters.py", line 688, in send
    raise ConnectTimeout(e, request=request)
requests.exceptions.ConnectTimeout: HTTPConnectionPool(host='61.43.54.35', port=8282): Max retries exceeded with url: /api (Caused by ConnectTimeoutError(<urllib3.connection.HTTPConnection object at 0x7f275306f5d0>, 'Connection to 61.43.54.35 timed out. (connect timeout=None)'))
여기까지 ImmutableMultiDict([])
 - - [18/Jul/2024:21:00:22 +0900] "POST /util/data_api HTTP/1.0" 500 265 "http://61.43.54.35:8484/" "Mozilla/5.0 (Windows NT 10.0; Win64; x64) AppleWebKit/537.36 (KHTML, like Gecko) Chrome/126.0.0.0 Safari/537.36 Edg/126.0.0.0"
[2024-07-18 21:08:47 +0900] [664] [INFO] Worker reloading: /home/web_ai/Project/app/main/routes.py modified
[2024-07-18 21:08:47 +0900] [664] [INFO] Worker exiting (pid: 664)
[2024-07-18 21:08:47 +0900] [738] [INFO] Booting worker with pid: 738
 - - [18/Jul/2024:21:08:58 +0900] "GET /load_content/summary?lastViewNumber=1 HTTP/1.0" 200 6258 "http://61.43.54.35:8484/" "Mozilla/5.0 (Windows NT 10.0; Win64; x64) AppleWebKit/537.36 (KHTML, like Gecko) Chrome/126.0.0.0 Safari/537.36 Edg/126.0.0.0"
 - - [18/Jul/2024:21:08:58 +0900] "GET /static/css/summary.css HTTP/1.0" 304 0 "http://61.43.54.35:8484/" "Mozilla/5.0 (Windows NT 10.0; Win64; x64) AppleWebKit/537.36 (KHTML, like Gecko) Chrome/126.0.0.0 Safari/537.36 Edg/126.0.0.0"
 - - [18/Jul/2024:21:08:58 +0900] "GET /static/scripts/summary.js HTTP/1.0" 304 0 "http://61.43.54.35:8484/" "Mozilla/5.0 (Windows NT 10.0; Win64; x64) AppleWebKit/537.36 (KHTML, like Gecko) Chrome/126.0.0.0 Safari/537.36 Edg/126.0.0.0"
 - - [18/Jul/2024:21:09:01 +0900] "GET / HTTP/1.0" 200 8290 "-" "Mozilla/5.0 (Windows NT 10.0; Win64; x64) AppleWebKit/537.36 (KHTML, like Gecko) Chrome/126.0.0.0 Safari/537.36 Edg/126.0.0.0"
 - - [18/Jul/2024:21:09:01 +0900] "GET /static/css/index.css HTTP/1.0" 304 0 "http://61.43.54.35:8484/" "Mozilla/5.0 (Windows NT 10.0; Win64; x64) AppleWebKit/537.36 (KHTML, like Gecko) Chrome/126.0.0.0 Safari/537.36 Edg/126.0.0.0"
 - - [18/Jul/2024:21:09:01 +0900] "GET /static/scripts/index.js HTTP/1.0" 304 0 "http://61.43.54.35:8484/" "Mozilla/5.0 (Windows NT 10.0; Win64; x64) AppleWebKit/537.36 (KHTML, like Gecko) Chrome/126.0.0.0 Safari/537.36 Edg/126.0.0.0"
 - - [18/Jul/2024:21:09:01 +0900] "GET /static/css/summary.css HTTP/1.0" 304 0 "http://61.43.54.35:8484/" "Mozilla/5.0 (Windows NT 10.0; Win64; x64) AppleWebKit/537.36 (KHTML, like Gecko) Chrome/126.0.0.0 Safari/537.36 Edg/126.0.0.0"
 - - [18/Jul/2024:21:09:01 +0900] "GET /static/scripts/summary.js HTTP/1.0" 304 0 "http://61.43.54.35:8484/" "Mozilla/5.0 (Windows NT 10.0; Win64; x64) AppleWebKit/537.36 (KHTML, like Gecko) Chrome/126.0.0.0 Safari/537.36 Edg/126.0.0.0"
 - - [18/Jul/2024:21:09:05 +0900] "GET /load_content/db_manager?lastViewNumber=1 HTTP/1.0" 200 4338 "http://61.43.54.35:8484/" "Mozilla/5.0 (Windows NT 10.0; Win64; x64) AppleWebKit/537.36 (KHTML, like Gecko) Chrome/126.0.0.0 Safari/537.36 Edg/126.0.0.0"
 - - [18/Jul/2024:21:09:05 +0900] "GET /static/css/db_manager.css HTTP/1.0" 304 0 "http://61.43.54.35:8484/" "Mozilla/5.0 (Windows NT 10.0; Win64; x64) AppleWebKit/537.36 (KHTML, like Gecko) Chrome/126.0.0.0 Safari/537.36 Edg/126.0.0.0"
 - - [18/Jul/2024:21:09:05 +0900] "GET /static/scripts/db_manager.js HTTP/1.0" 304 0 "http://61.43.54.35:8484/" "Mozilla/5.0 (Windows NT 10.0; Win64; x64) AppleWebKit/537.36 (KHTML, like Gecko) Chrome/126.0.0.0 Safari/537.36 Edg/126.0.0.0"
[2024-07-18 21:11:17,593] ERROR in app: Exception on /util/data_api [POST]
Traceback (most recent call last):
  File "/home/web_ai/Project/venv/lib/python3.11/site-packages/urllib3/connection.py", line 196, in _new_conn
    sock = connection.create_connection(
           ^^^^^^^^^^^^^^^^^^^^^^^^^^^^^
  File "/home/web_ai/Project/venv/lib/python3.11/site-packages/urllib3/util/connection.py", line 85, in create_connection
    raise err
  File "/home/web_ai/Project/venv/lib/python3.11/site-packages/urllib3/util/connection.py", line 73, in create_connection
    sock.connect(sa)
TimeoutError: [Errno 110] Connection timed out

The above exception was the direct cause of the following exception:

Traceback (most recent call last):
  File "/home/web_ai/Project/venv/lib/python3.11/site-packages/urllib3/connectionpool.py", line 789, in urlopen
    response = self._make_request(
               ^^^^^^^^^^^^^^^^^^^
  File "/home/web_ai/Project/venv/lib/python3.11/site-packages/urllib3/connectionpool.py", line 495, in _make_request
    conn.request(
  File "/home/web_ai/Project/venv/lib/python3.11/site-packages/urllib3/connection.py", line 398, in request
    self.endheaders()
  File "/usr/lib/python3.11/http/client.py", line 1298, in endheaders
    self._send_output(message_body, encode_chunked=encode_chunked)
  File "/usr/lib/python3.11/http/client.py", line 1058, in _send_output
    self.send(msg)
  File "/usr/lib/python3.11/http/client.py", line 996, in send
    self.connect()
  File "/home/web_ai/Project/venv/lib/python3.11/site-packages/urllib3/connection.py", line 236, in connect
    self.sock = self._new_conn()
                ^^^^^^^^^^^^^^^^
  File "/home/web_ai/Project/venv/lib/python3.11/site-packages/urllib3/connection.py", line 205, in _new_conn
    raise ConnectTimeoutError(
urllib3.exceptions.ConnectTimeoutError: (<urllib3.connection.HTTPConnection object at 0x7f2753945950>, 'Connection to 61.43.54.35 timed out. (connect timeout=None)')

The above exception was the direct cause of the following exception:

Traceback (most recent call last):
  File "/home/web_ai/Project/venv/lib/python3.11/site-packages/requests/adapters.py", line 667, in send
    resp = conn.urlopen(
           ^^^^^^^^^^^^^
  File "/home/web_ai/Project/venv/lib/python3.11/site-packages/urllib3/connectionpool.py", line 843, in urlopen
    retries = retries.increment(
              ^^^^^^^^^^^^^^^^^^
  File "/home/web_ai/Project/venv/lib/python3.11/site-packages/urllib3/util/retry.py", line 519, in increment
    raise MaxRetryError(_pool, url, reason) from reason  # type: ignore[arg-type]
    ^^^^^^^^^^^^^^^^^^^^^^^^^^^^^^^^^^^^^^^^^^^^^^^^^^^
urllib3.exceptions.MaxRetryError: HTTPConnectionPool(host='61.43.54.35', port=8282): Max retries exceeded with url: /api (Caused by ConnectTimeoutError(<urllib3.connection.HTTPConnection object at 0x7f2753945950>, 'Connection to 61.43.54.35 timed out. (connect timeout=None)'))

During handling of the above exception, another exception occurred:

Traceback (most recent call last):
  File "/home/web_ai/Project/venv/lib/python3.11/site-packages/flask/app.py", line 1473, in wsgi_app
    response = self.full_dispatch_request()
               ^^^^^^^^^^^^^^^^^^^^^^^^^^^^
  File "/home/web_ai/Project/venv/lib/python3.11/site-packages/flask/app.py", line 882, in full_dispatch_request
    rv = self.handle_user_exception(e)
         ^^^^^^^^^^^^^^^^^^^^^^^^^^^^^
  File "/home/web_ai/Project/venv/lib/python3.11/site-packages/flask/app.py", line 880, in full_dispatch_request
    rv = self.dispatch_request()
         ^^^^^^^^^^^^^^^^^^^^^^^
  File "/home/web_ai/Project/venv/lib/python3.11/site-packages/flask/app.py", line 865, in dispatch_request
    return self.ensure_sync(self.view_functions[rule.endpoint])(**view_args)  # type: ignore[no-any-return]
           ^^^^^^^^^^^^^^^^^^^^^^^^^^^^^^^^^^^^^^^^^^^^^^^^^^^^^^^^^^^^^^^^^
  File "/home/web_ai/Project/app/main/routes.py", line 390, in data_api
    response = requests.post(DATA_API_ADDRESS, data=data)
               ^^^^^^^^^^^^^^^^^^^^^^^^^^^^^^^^^^^^^^^^^^
  File "/home/web_ai/Project/venv/lib/python3.11/site-packages/requests/api.py", line 115, in post
    return request("post", url, data=data, json=json, **kwargs)
           ^^^^^^^^^^^^^^^^^^^^^^^^^^^^^^^^^^^^^^^^^^^^^^^^^^^^
  File "/home/web_ai/Project/venv/lib/python3.11/site-packages/requests/api.py", line 59, in request
    return session.request(method=method, url=url, **kwargs)
           ^^^^^^^^^^^^^^^^^^^^^^^^^^^^^^^^^^^^^^^^^^^^^^^^^
  File "/home/web_ai/Project/venv/lib/python3.11/site-packages/requests/sessions.py", line 589, in request
    resp = self.send(prep, **send_kwargs)
           ^^^^^^^^^^^^^^^^^^^^^^^^^^^^^^
  File "/home/web_ai/Project/venv/lib/python3.11/site-packages/requests/sessions.py", line 703, in send
    r = adapter.send(request, **kwargs)
        ^^^^^^^^^^^^^^^^^^^^^^^^^^^^^^^
  File "/home/web_ai/Project/venv/lib/python3.11/site-packages/requests/adapters.py", line 688, in send
    raise ConnectTimeout(e, request=request)
requests.exceptions.ConnectTimeout: HTTPConnectionPool(host='61.43.54.35', port=8282): Max retries exceeded with url: /api (Caused by ConnectTimeoutError(<urllib3.connection.HTTPConnection object at 0x7f2753945950>, 'Connection to 61.43.54.35 timed out. (connect timeout=None)'))
여기까지 ImmutableMultiDict([])
 - - [18/Jul/2024:21:11:17 +0900] "POST /util/data_api HTTP/1.0" 500 265 "http://61.43.54.35:8484/" "Mozilla/5.0 (Windows NT 10.0; Win64; x64) AppleWebKit/537.36 (KHTML, like Gecko) Chrome/126.0.0.0 Safari/537.36 Edg/126.0.0.0"
 - - [18/Jul/2024:21:11:17 +0900] "GET /static/css/db_manager.css HTTP/1.0" 304 0 "http://61.43.54.35:8484/" "Mozilla/5.0 (Windows NT 10.0; Win64; x64) AppleWebKit/537.36 (KHTML, like Gecko) Chrome/126.0.0.0 Safari/537.36 Edg/126.0.0.0"
 - - [18/Jul/2024:21:11:17 +0900] "GET /static/css/index.css HTTP/1.0" 304 0 "http://61.43.54.35:8484/" "Mozilla/5.0 (Windows NT 10.0; Win64; x64) AppleWebKit/537.36 (KHTML, like Gecko) Chrome/126.0.0.0 Safari/537.36 Edg/126.0.0.0"
[2024-07-18 21:11:41 +0900] [738] [INFO] Worker reloading: /home/web_ai/Project/app/main/routes.py modified
[2024-07-18 21:11:41 +0900] [738] [INFO] Worker exiting (pid: 738)
[2024-07-18 21:11:41 +0900] [769] [INFO] Booting worker with pid: 769
 - - [18/Jul/2024:21:27:02 +0900] "GET /load_content/db_manager?lastViewNumber=1 HTTP/1.0" 200 4338 "http://61.43.54.35:8484/" "Mozilla/5.0 (Windows NT 10.0; Win64; x64) AppleWebKit/537.36 (KHTML, like Gecko) Chrome/126.0.0.0 Safari/537.36 Edg/126.0.0.0"
 - - [18/Jul/2024:21:27:02 +0900] "GET /static/css/db_manager.css HTTP/1.0" 304 0 "http://61.43.54.35:8484/" "Mozilla/5.0 (Windows NT 10.0; Win64; x64) AppleWebKit/537.36 (KHTML, like Gecko) Chrome/126.0.0.0 Safari/537.36 Edg/126.0.0.0"
 - - [18/Jul/2024:21:27:02 +0900] "GET /static/scripts/db_manager.js HTTP/1.0" 304 0 "http://61.43.54.35:8484/" "Mozilla/5.0 (Windows NT 10.0; Win64; x64) AppleWebKit/537.36 (KHTML, like Gecko) Chrome/126.0.0.0 Safari/537.36 Edg/126.0.0.0"
[2024-07-18 21:29:14,841] ERROR in app: Exception on /util/data_api [POST]
Traceback (most recent call last):
  File "/home/web_ai/Project/venv/lib/python3.11/site-packages/urllib3/connection.py", line 196, in _new_conn
    sock = connection.create_connection(
           ^^^^^^^^^^^^^^^^^^^^^^^^^^^^^
  File "/home/web_ai/Project/venv/lib/python3.11/site-packages/urllib3/util/connection.py", line 85, in create_connection
    raise err
  File "/home/web_ai/Project/venv/lib/python3.11/site-packages/urllib3/util/connection.py", line 73, in create_connection
    sock.connect(sa)
TimeoutError: [Errno 110] Connection timed out

The above exception was the direct cause of the following exception:

Traceback (most recent call last):
  File "/home/web_ai/Project/venv/lib/python3.11/site-packages/urllib3/connectionpool.py", line 789, in urlopen
    response = self._make_request(
               ^^^^^^^^^^^^^^^^^^^
  File "/home/web_ai/Project/venv/lib/python3.11/site-packages/urllib3/connectionpool.py", line 495, in _make_request
    conn.request(
  File "/home/web_ai/Project/venv/lib/python3.11/site-packages/urllib3/connection.py", line 398, in request
    self.endheaders()
  File "/usr/lib/python3.11/http/client.py", line 1298, in endheaders
    self._send_output(message_body, encode_chunked=encode_chunked)
  File "/usr/lib/python3.11/http/client.py", line 1058, in _send_output
    self.send(msg)
  File "/usr/lib/python3.11/http/client.py", line 996, in send
    self.connect()
  File "/home/web_ai/Project/venv/lib/python3.11/site-packages/urllib3/connection.py", line 236, in connect
    self.sock = self._new_conn()
                ^^^^^^^^^^^^^^^^
  File "/home/web_ai/Project/venv/lib/python3.11/site-packages/urllib3/connection.py", line 205, in _new_conn
    raise ConnectTimeoutError(
urllib3.exceptions.ConnectTimeoutError: (<urllib3.connection.HTTPConnection object at 0x7f27539ba010>, 'Connection to 61.43.54.35 timed out. (connect timeout=None)')

The above exception was the direct cause of the following exception:

Traceback (most recent call last):
  File "/home/web_ai/Project/venv/lib/python3.11/site-packages/requests/adapters.py", line 667, in send
    resp = conn.urlopen(
           ^^^^^^^^^^^^^
  File "/home/web_ai/Project/venv/lib/python3.11/site-packages/urllib3/connectionpool.py", line 843, in urlopen
    retries = retries.increment(
              ^^^^^^^^^^^^^^^^^^
  File "/home/web_ai/Project/venv/lib/python3.11/site-packages/urllib3/util/retry.py", line 519, in increment
    raise MaxRetryError(_pool, url, reason) from reason  # type: ignore[arg-type]
    ^^^^^^^^^^^^^^^^^^^^^^^^^^^^^^^^^^^^^^^^^^^^^^^^^^^
urllib3.exceptions.MaxRetryError: HTTPConnectionPool(host='61.43.54.35', port=8282): Max retries exceeded with url: /api (Caused by ConnectTimeoutError(<urllib3.connection.HTTPConnection object at 0x7f27539ba010>, 'Connection to 61.43.54.35 timed out. (connect timeout=None)'))

During handling of the above exception, another exception occurred:

Traceback (most recent call last):
  File "/home/web_ai/Project/venv/lib/python3.11/site-packages/flask/app.py", line 1473, in wsgi_app
    response = self.full_dispatch_request()
               ^^^^^^^^^^^^^^^^^^^^^^^^^^^^
  File "/home/web_ai/Project/venv/lib/python3.11/site-packages/flask/app.py", line 882, in full_dispatch_request
    rv = self.handle_user_exception(e)
         ^^^^^^^^^^^^^^^^^^^^^^^^^^^^^
  File "/home/web_ai/Project/venv/lib/python3.11/site-packages/flask/app.py", line 880, in full_dispatch_request
    rv = self.dispatch_request()
         ^^^^^^^^^^^^^^^^^^^^^^^
  File "/home/web_ai/Project/venv/lib/python3.11/site-packages/flask/app.py", line 865, in dispatch_request
    return self.ensure_sync(self.view_functions[rule.endpoint])(**view_args)  # type: ignore[no-any-return]
           ^^^^^^^^^^^^^^^^^^^^^^^^^^^^^^^^^^^^^^^^^^^^^^^^^^^^^^^^^^^^^^^^^
  File "/home/web_ai/Project/app/main/routes.py", line 389, in data_api
    response = requests.post(DATA_API_ADDRESS, data=data)
               ^^^^^^^^^^^^^^^^^^^^^^^^^^^^^^^^^^^^^^^^^^
  File "/home/web_ai/Project/venv/lib/python3.11/site-packages/requests/api.py", line 115, in post
    return request("post", url, data=data, json=json, **kwargs)
           ^^^^^^^^^^^^^^^^^^^^^^^^^^^^^^^^^^^^^^^^^^^^^^^^^^^^
  File "/home/web_ai/Project/venv/lib/python3.11/site-packages/requests/api.py", line 59, in request
    return session.request(method=method, url=url, **kwargs)
           ^^^^^^^^^^^^^^^^^^^^^^^^^^^^^^^^^^^^^^^^^^^^^^^^^
  File "/home/web_ai/Project/venv/lib/python3.11/site-packages/requests/sessions.py", line 589, in request
    resp = self.send(prep, **send_kwargs)
           ^^^^^^^^^^^^^^^^^^^^^^^^^^^^^^
  File "/home/web_ai/Project/venv/lib/python3.11/site-packages/requests/sessions.py", line 703, in send
    r = adapter.send(request, **kwargs)
        ^^^^^^^^^^^^^^^^^^^^^^^^^^^^^^^
  File "/home/web_ai/Project/venv/lib/python3.11/site-packages/requests/adapters.py", line 688, in send
    raise ConnectTimeout(e, request=request)
requests.exceptions.ConnectTimeout: HTTPConnectionPool(host='61.43.54.35', port=8282): Max retries exceeded with url: /api (Caused by ConnectTimeoutError(<urllib3.connection.HTTPConnection object at 0x7f27539ba010>, 'Connection to 61.43.54.35 timed out. (connect timeout=None)'))
여기까지 ImmutableMultiDict([])
 - - [18/Jul/2024:21:29:14 +0900] "POST /util/data_api HTTP/1.0" 500 265 "http://61.43.54.35:8484/" "Mozilla/5.0 (Windows NT 10.0; Win64; x64) AppleWebKit/537.36 (KHTML, like Gecko) Chrome/126.0.0.0 Safari/537.36 Edg/126.0.0.0"
[2024-07-18 21:29:25 +0900] [769] [INFO] Worker reloading: /home/web_ai/Project/app/main/routes.py modified
[2024-07-18 21:29:25 +0900] [769] [INFO] Worker exiting (pid: 769)
[2024-07-18 21:29:25 +0900] [820] [INFO] Booting worker with pid: 820
 - - [18/Jul/2024:21:29:28 +0900] "GET /load_content/db_manager?lastViewNumber=1 HTTP/1.0" 200 4338 "http://61.43.54.35:8484/" "Mozilla/5.0 (Windows NT 10.0; Win64; x64) AppleWebKit/537.36 (KHTML, like Gecko) Chrome/126.0.0.0 Safari/537.36 Edg/126.0.0.0"
 - - [18/Jul/2024:21:29:28 +0900] "GET /static/css/db_manager.css HTTP/1.0" 304 0 "http://61.43.54.35:8484/" "Mozilla/5.0 (Windows NT 10.0; Win64; x64) AppleWebKit/537.36 (KHTML, like Gecko) Chrome/126.0.0.0 Safari/537.36 Edg/126.0.0.0"
 - - [18/Jul/2024:21:29:28 +0900] "GET /static/scripts/db_manager.js HTTP/1.0" 304 0 "http://61.43.54.35:8484/" "Mozilla/5.0 (Windows NT 10.0; Win64; x64) AppleWebKit/537.36 (KHTML, like Gecko) Chrome/126.0.0.0 Safari/537.36 Edg/126.0.0.0"
[2024-07-18 21:31:44,345] ERROR in app: Exception on /util/data_api [POST]
Traceback (most recent call last):
  File "/home/web_ai/Project/venv/lib/python3.11/site-packages/urllib3/connection.py", line 196, in _new_conn
    sock = connection.create_connection(
           ^^^^^^^^^^^^^^^^^^^^^^^^^^^^^
  File "/home/web_ai/Project/venv/lib/python3.11/site-packages/urllib3/util/connection.py", line 85, in create_connection
    raise err
  File "/home/web_ai/Project/venv/lib/python3.11/site-packages/urllib3/util/connection.py", line 73, in create_connection
    sock.connect(sa)
TimeoutError: [Errno 110] Connection timed out

The above exception was the direct cause of the following exception:

Traceback (most recent call last):
  File "/home/web_ai/Project/venv/lib/python3.11/site-packages/urllib3/connectionpool.py", line 789, in urlopen
    response = self._make_request(
               ^^^^^^^^^^^^^^^^^^^
  File "/home/web_ai/Project/venv/lib/python3.11/site-packages/urllib3/connectionpool.py", line 495, in _make_request
    conn.request(
  File "/home/web_ai/Project/venv/lib/python3.11/site-packages/urllib3/connection.py", line 398, in request
    self.endheaders()
  File "/usr/lib/python3.11/http/client.py", line 1298, in endheaders
    self._send_output(message_body, encode_chunked=encode_chunked)
  File "/usr/lib/python3.11/http/client.py", line 1058, in _send_output
    self.send(msg)
  File "/usr/lib/python3.11/http/client.py", line 996, in send
    self.connect()
  File "/home/web_ai/Project/venv/lib/python3.11/site-packages/urllib3/connection.py", line 236, in connect
    self.sock = self._new_conn()
                ^^^^^^^^^^^^^^^^
  File "/home/web_ai/Project/venv/lib/python3.11/site-packages/urllib3/connection.py", line 205, in _new_conn
    raise ConnectTimeoutError(
urllib3.exceptions.ConnectTimeoutError: (<urllib3.connection.HTTPConnection object at 0x7f27539bdfd0>, 'Connection to 61.43.54.35 timed out. (connect timeout=None)')

The above exception was the direct cause of the following exception:

Traceback (most recent call last):
  File "/home/web_ai/Project/venv/lib/python3.11/site-packages/requests/adapters.py", line 667, in send
    resp = conn.urlopen(
           ^^^^^^^^^^^^^
  File "/home/web_ai/Project/venv/lib/python3.11/site-packages/urllib3/connectionpool.py", line 843, in urlopen
    retries = retries.increment(
              ^^^^^^^^^^^^^^^^^^
  File "/home/web_ai/Project/venv/lib/python3.11/site-packages/urllib3/util/retry.py", line 519, in increment
    raise MaxRetryError(_pool, url, reason) from reason  # type: ignore[arg-type]
    ^^^^^^^^^^^^^^^^^^^^^^^^^^^^^^^^^^^^^^^^^^^^^^^^^^^
urllib3.exceptions.MaxRetryError: HTTPConnectionPool(host='61.43.54.35', port=8282): Max retries exceeded with url: /api (Caused by ConnectTimeoutError(<urllib3.connection.HTTPConnection object at 0x7f27539bdfd0>, 'Connection to 61.43.54.35 timed out. (connect timeout=None)'))

During handling of the above exception, another exception occurred:

Traceback (most recent call last):
  File "/home/web_ai/Project/venv/lib/python3.11/site-packages/flask/app.py", line 1473, in wsgi_app
    response = self.full_dispatch_request()
               ^^^^^^^^^^^^^^^^^^^^^^^^^^^^
  File "/home/web_ai/Project/venv/lib/python3.11/site-packages/flask/app.py", line 882, in full_dispatch_request
    rv = self.handle_user_exception(e)
         ^^^^^^^^^^^^^^^^^^^^^^^^^^^^^
  File "/home/web_ai/Project/venv/lib/python3.11/site-packages/flask/app.py", line 880, in full_dispatch_request
    rv = self.dispatch_request()
         ^^^^^^^^^^^^^^^^^^^^^^^
  File "/home/web_ai/Project/venv/lib/python3.11/site-packages/flask/app.py", line 865, in dispatch_request
    return self.ensure_sync(self.view_functions[rule.endpoint])(**view_args)  # type: ignore[no-any-return]
           ^^^^^^^^^^^^^^^^^^^^^^^^^^^^^^^^^^^^^^^^^^^^^^^^^^^^^^^^^^^^^^^^^
  File "/home/web_ai/Project/app/main/routes.py", line 389, in data_api
    response = requests.post(DATA_API_ADDRESS, json=data_1)
               ^^^^^^^^^^^^^^^^^^^^^^^^^^^^^^^^^^^^^^^^^^^^
  File "/home/web_ai/Project/venv/lib/python3.11/site-packages/requests/api.py", line 115, in post
    return request("post", url, data=data, json=json, **kwargs)
           ^^^^^^^^^^^^^^^^^^^^^^^^^^^^^^^^^^^^^^^^^^^^^^^^^^^^
  File "/home/web_ai/Project/venv/lib/python3.11/site-packages/requests/api.py", line 59, in request
    return session.request(method=method, url=url, **kwargs)
           ^^^^^^^^^^^^^^^^^^^^^^^^^^^^^^^^^^^^^^^^^^^^^^^^^
  File "/home/web_ai/Project/venv/lib/python3.11/site-packages/requests/sessions.py", line 589, in request
    resp = self.send(prep, **send_kwargs)
           ^^^^^^^^^^^^^^^^^^^^^^^^^^^^^^
  File "/home/web_ai/Project/venv/lib/python3.11/site-packages/requests/sessions.py", line 703, in send
    r = adapter.send(request, **kwargs)
        ^^^^^^^^^^^^^^^^^^^^^^^^^^^^^^^
  File "/home/web_ai/Project/venv/lib/python3.11/site-packages/requests/adapters.py", line 688, in send
    raise ConnectTimeout(e, request=request)
requests.exceptions.ConnectTimeout: HTTPConnectionPool(host='61.43.54.35', port=8282): Max retries exceeded with url: /api (Caused by ConnectTimeoutError(<urllib3.connection.HTTPConnection object at 0x7f27539bdfd0>, 'Connection to 61.43.54.35 timed out. (connect timeout=None)'))
여기까지 ImmutableMultiDict([])
 - - [18/Jul/2024:21:31:44 +0900] "POST /util/data_api HTTP/1.0" 500 265 "http://61.43.54.35:8484/" "Mozilla/5.0 (Windows NT 10.0; Win64; x64) AppleWebKit/537.36 (KHTML, like Gecko) Chrome/126.0.0.0 Safari/537.36 Edg/126.0.0.0"
 - - [18/Jul/2024:21:43:21 +0900] "GET /load_content/db_manager?lastViewNumber=1 HTTP/1.0" 200 4338 "http://61.43.54.35:8484/" "Mozilla/5.0 (Windows NT 10.0; Win64; x64) AppleWebKit/537.36 (KHTML, like Gecko) Chrome/126.0.0.0 Safari/537.36 Edg/126.0.0.0"
 - - [18/Jul/2024:21:43:21 +0900] "GET /static/scripts/db_manager.js HTTP/1.0" 304 0 "http://61.43.54.35:8484/" "Mozilla/5.0 (Windows NT 10.0; Win64; x64) AppleWebKit/537.36 (KHTML, like Gecko) Chrome/126.0.0.0 Safari/537.36 Edg/126.0.0.0"
 - - [18/Jul/2024:21:43:21 +0900] "GET /static/css/db_manager.css HTTP/1.0" 304 0 "http://61.43.54.35:8484/" "Mozilla/5.0 (Windows NT 10.0; Win64; x64) AppleWebKit/537.36 (KHTML, like Gecko) Chrome/126.0.0.0 Safari/537.36 Edg/126.0.0.0"
[2024-07-18 21:45:33,784] ERROR in app: Exception on /util/data_api [POST]
Traceback (most recent call last):
  File "/home/web_ai/Project/venv/lib/python3.11/site-packages/urllib3/connection.py", line 196, in _new_conn
    sock = connection.create_connection(
           ^^^^^^^^^^^^^^^^^^^^^^^^^^^^^
  File "/home/web_ai/Project/venv/lib/python3.11/site-packages/urllib3/util/connection.py", line 85, in create_connection
    raise err
  File "/home/web_ai/Project/venv/lib/python3.11/site-packages/urllib3/util/connection.py", line 73, in create_connection
    sock.connect(sa)
TimeoutError: [Errno 110] Connection timed out

The above exception was the direct cause of the following exception:

Traceback (most recent call last):
  File "/home/web_ai/Project/venv/lib/python3.11/site-packages/urllib3/connectionpool.py", line 789, in urlopen
    response = self._make_request(
               ^^^^^^^^^^^^^^^^^^^
  File "/home/web_ai/Project/venv/lib/python3.11/site-packages/urllib3/connectionpool.py", line 495, in _make_request
    conn.request(
  File "/home/web_ai/Project/venv/lib/python3.11/site-packages/urllib3/connection.py", line 398, in request
    self.endheaders()
  File "/usr/lib/python3.11/http/client.py", line 1298, in endheaders
    self._send_output(message_body, encode_chunked=encode_chunked)
  File "/usr/lib/python3.11/http/client.py", line 1058, in _send_output
    self.send(msg)
  File "/usr/lib/python3.11/http/client.py", line 996, in send
    self.connect()
  File "/home/web_ai/Project/venv/lib/python3.11/site-packages/urllib3/connection.py", line 236, in connect
    self.sock = self._new_conn()
                ^^^^^^^^^^^^^^^^
  File "/home/web_ai/Project/venv/lib/python3.11/site-packages/urllib3/connection.py", line 205, in _new_conn
    raise ConnectTimeoutError(
urllib3.exceptions.ConnectTimeoutError: (<urllib3.connection.HTTPConnection object at 0x7f275306cc10>, 'Connection to 61.43.54.35 timed out. (connect timeout=None)')

The above exception was the direct cause of the following exception:

Traceback (most recent call last):
  File "/home/web_ai/Project/venv/lib/python3.11/site-packages/requests/adapters.py", line 667, in send
    resp = conn.urlopen(
           ^^^^^^^^^^^^^
  File "/home/web_ai/Project/venv/lib/python3.11/site-packages/urllib3/connectionpool.py", line 843, in urlopen
    retries = retries.increment(
              ^^^^^^^^^^^^^^^^^^
  File "/home/web_ai/Project/venv/lib/python3.11/site-packages/urllib3/util/retry.py", line 519, in increment
    raise MaxRetryError(_pool, url, reason) from reason  # type: ignore[arg-type]
    ^^^^^^^^^^^^^^^^^^^^^^^^^^^^^^^^^^^^^^^^^^^^^^^^^^^
urllib3.exceptions.MaxRetryError: HTTPConnectionPool(host='61.43.54.35', port=8282): Max retries exceeded with url: /api (Caused by ConnectTimeoutError(<urllib3.connection.HTTPConnection object at 0x7f275306cc10>, 'Connection to 61.43.54.35 timed out. (connect timeout=None)'))

During handling of the above exception, another exception occurred:

Traceback (most recent call last):
  File "/home/web_ai/Project/venv/lib/python3.11/site-packages/flask/app.py", line 1473, in wsgi_app
    response = self.full_dispatch_request()
               ^^^^^^^^^^^^^^^^^^^^^^^^^^^^
  File "/home/web_ai/Project/venv/lib/python3.11/site-packages/flask/app.py", line 882, in full_dispatch_request
    rv = self.handle_user_exception(e)
         ^^^^^^^^^^^^^^^^^^^^^^^^^^^^^
  File "/home/web_ai/Project/venv/lib/python3.11/site-packages/flask/app.py", line 880, in full_dispatch_request
    rv = self.dispatch_request()
         ^^^^^^^^^^^^^^^^^^^^^^^
  File "/home/web_ai/Project/venv/lib/python3.11/site-packages/flask/app.py", line 865, in dispatch_request
    return self.ensure_sync(self.view_functions[rule.endpoint])(**view_args)  # type: ignore[no-any-return]
           ^^^^^^^^^^^^^^^^^^^^^^^^^^^^^^^^^^^^^^^^^^^^^^^^^^^^^^^^^^^^^^^^^
  File "/home/web_ai/Project/app/main/routes.py", line 389, in data_api
    response = requests.post(DATA_API_ADDRESS, json=data_1)
               ^^^^^^^^^^^^^^^^^^^^^^^^^^^^^^^^^^^^^^^^^^^^
  File "/home/web_ai/Project/venv/lib/python3.11/site-packages/requests/api.py", line 115, in post
    return request("post", url, data=data, json=json, **kwargs)
           ^^^^^^^^^^^^^^^^^^^^^^^^^^^^^^^^^^^^^^^^^^^^^^^^^^^^
  File "/home/web_ai/Project/venv/lib/python3.11/site-packages/requests/api.py", line 59, in request
    return session.request(method=method, url=url, **kwargs)
           ^^^^^^^^^^^^^^^^^^^^^^^^^^^^^^^^^^^^^^^^^^^^^^^^^
  File "/home/web_ai/Project/venv/lib/python3.11/site-packages/requests/sessions.py", line 589, in request
    resp = self.send(prep, **send_kwargs)
           ^^^^^^^^^^^^^^^^^^^^^^^^^^^^^^
  File "/home/web_ai/Project/venv/lib/python3.11/site-packages/requests/sessions.py", line 703, in send
    r = adapter.send(request, **kwargs)
        ^^^^^^^^^^^^^^^^^^^^^^^^^^^^^^^
  File "/home/web_ai/Project/venv/lib/python3.11/site-packages/requests/adapters.py", line 688, in send
    raise ConnectTimeout(e, request=request)
requests.exceptions.ConnectTimeout: HTTPConnectionPool(host='61.43.54.35', port=8282): Max retries exceeded with url: /api (Caused by ConnectTimeoutError(<urllib3.connection.HTTPConnection object at 0x7f275306cc10>, 'Connection to 61.43.54.35 timed out. (connect timeout=None)'))
여기까지 ImmutableMultiDict([])
 - - [18/Jul/2024:21:45:33 +0900] "POST /util/data_api HTTP/1.0" 500 265 "http://61.43.54.35:8484/" "Mozilla/5.0 (Windows NT 10.0; Win64; x64) AppleWebKit/537.36 (KHTML, like Gecko) Chrome/126.0.0.0 Safari/537.36 Edg/126.0.0.0"
[2024-07-18 21:55:45 +0900] [820] [INFO] Worker reloading: /home/web_ai/Project/app/secret/secret.py modified
[2024-07-18 21:55:45 +0900] [820] [INFO] Worker exiting (pid: 820)
[2024-07-18 21:55:45 +0900] [901] [INFO] Booting worker with pid: 901
